<?xml version="1.0" ?>
<!--
  Headless camera streaming demo.

  Launch with:
    gz sim -s -r --headless-rendering headless_camera.sdf

  Then open viewer.html in a browser to see the camera feed
  and 3D scene streamed via WebSocket on port 9002.
-->
<sdf version="1.11">
  <world name="headless_camera">

    <physics name="1ms" type="ignored">
      <max_step_size>0.001</max_step_size>
      <real_time_factor>1.0</real_time_factor>
    </physics>

    <!-- Core system plugins -->
    <plugin
        filename="gz-sim-physics-system"
        name="gz::sim::systems::Physics">
    </plugin>
    <plugin
        filename="gz-sim-user-commands-system"
        name="gz::sim::systems::UserCommands">
    </plugin>
    <plugin
        filename="gz-sim-scene-broadcaster-system"
        name="gz::sim::systems::SceneBroadcaster">
    </plugin>

    <!-- Sensors system - required for camera rendering in headless mode -->
    <plugin
        filename="gz-sim-sensors-system"
        name="gz::sim::systems::Sensors">
      <render_engine>ogre2</render_engine>
    </plugin>

    <!-- WebSocket server - streams scene + image data to web clients -->
    <plugin
        filename="gz-sim-websocket-server-system"
        name="gz::sim::systems::WebsocketServer">
      <publication_hz>30</publication_hz>
      <port>9002</port>
      <max_connections>-1</max_connections>
    </plugin>

    <!-- Camera stream - encodes H.264 and pushes to MediaMTX via WHIP -->
    <plugin
        filename="gz-sim-camera-stream-system"
        name="gz::sim::systems::CameraStream">
      <topic>/stream/control</topic>
      <default_bitrate>4000000</default_bitrate>
      <default_fps>30</default_fps>
    </plugin>

    <!-- Scene settings -->
    <scene>
      <ambient>0.6 0.6 0.6 1.0</ambient>
      <background>0.4 0.6 0.9 1.0</background>
    </scene>

    <!-- Sun -->
    <light type="directional" name="sun">
      <cast_shadows>true</cast_shadows>
      <pose>0 0 10 0 0 0</pose>
      <diffuse>1.0 1.0 1.0 1</diffuse>
      <specular>0.5 0.5 0.5 1</specular>
      <direction>-0.5 0.1 -0.9</direction>
    </light>

    <!-- Ground plane -->
    <model name="ground_plane">
      <static>true</static>
      <link name="link">
        <collision name="collision">
          <geometry>
            <plane>
              <normal>0 0 1</normal>
              <size>100 100</size>
            </plane>
          </geometry>
        </collision>
        <visual name="visual">
          <geometry>
            <plane>
              <normal>0 0 1</normal>
              <size>100 100</size>
            </plane>
          </geometry>
          <material>
            <ambient>0.8 0.8 0.8 1</ambient>
            <diffuse>0.8 0.8 0.8 1</diffuse>
            <specular>0.8 0.8 0.8 1</specular>
          </material>
        </visual>
      </link>
    </model>

    <!-- Objects dropped from height so motion is visible -->
    <model name="red_box">
      <pose>2 0 5 0.3 0.2 0</pose>
      <link name="link">
        <inertial>
          <mass>1.0</mass>
          <inertia>
            <ixx>0.167</ixx><iyy>0.167</iyy><izz>0.167</izz>
          </inertia>
        </inertial>
        <collision name="collision">
          <geometry><box><size>1 1 1</size></box></geometry>
        </collision>
        <visual name="visual">
          <geometry><box><size>1 1 1</size></box></geometry>
          <material>
            <ambient>0.8 0.1 0.1 1</ambient>
            <diffuse>0.8 0.1 0.1 1</diffuse>
            <specular>0.8 0.1 0.1 1</specular>
          </material>
        </visual>
      </link>
    </model>

    <model name="green_sphere">
      <pose>2 2 8 0 0 0</pose>
      <link name="link">
        <inertial>
          <mass>1.0</mass>
          <inertia>
            <ixx>0.1</ixx><iyy>0.1</iyy><izz>0.1</izz>
          </inertia>
        </inertial>
        <collision name="collision">
          <geometry><sphere><radius>0.5</radius></sphere></geometry>
        </collision>
        <visual name="visual">
          <geometry><sphere><radius>0.5</radius></sphere></geometry>
          <material>
            <ambient>0.1 0.8 0.1 1</ambient>
            <diffuse>0.1 0.8 0.1 1</diffuse>
            <specular>0.1 0.8 0.1 1</specular>
          </material>
        </visual>
      </link>
    </model>

    <model name="blue_cylinder">
      <pose>2 -2 12 0.5 0.3 0</pose>
      <link name="link">
        <inertial>
          <mass>1.0</mass>
          <inertia>
            <ixx>0.146</ixx><iyy>0.146</iyy><izz>0.125</izz>
          </inertia>
        </inertial>
        <collision name="collision">
          <geometry><cylinder><radius>0.5</radius><length>1.0</length></cylinder></geometry>
        </collision>
        <visual name="visual">
          <geometry><cylinder><radius>0.5</radius><length>1.0</length></cylinder></geometry>
          <material>
            <ambient>0.1 0.1 0.8 1</ambient>
            <diffuse>0.1 0.1 0.8 1</diffuse>
            <specular>0.1 0.1 0.8 1</specular>
          </material>
        </visual>
      </link>
    </model>

    <!-- Spinning arm on a motorized joint for continuous visible motion -->
    <model name="spinner">
      <pose>0 0 0 0 0 0</pose>
      <link name="base">
        <inertial><mass>100</mass></inertial>
        <collision name="collision">
          <geometry><cylinder><radius>0.3</radius><length>0.1</length></cylinder></geometry>
        </collision>
        <visual name="visual">
          <geometry><cylinder><radius>0.3</radius><length>0.1</length></cylinder></geometry>
          <material>
            <ambient>0.4 0.4 0.4 1</ambient>
            <diffuse>0.4 0.4 0.4 1</diffuse>
          </material>
        </visual>
      </link>
      <link name="arm">
        <pose>0 0 0.15 0 0 0</pose>
        <inertial>
          <pose>1 0 0 0 0 0</pose>
          <mass>2.0</mass>
          <inertia>
            <ixx>0.01</ixx><iyy>0.67</iyy><izz>0.67</izz>
          </inertia>
        </inertial>
        <visual name="arm_visual">
          <pose>1 0 0 0 1.5708 0</pose>
          <geometry><cylinder><radius>0.08</radius><length>2.0</length></cylinder></geometry>
          <material>
            <ambient>0.9 0.6 0.0 1</ambient>
            <diffuse>0.9 0.6 0.0 1</diffuse>
            <specular>0.9 0.6 0.0 1</specular>
          </material>
        </visual>
        <visual name="tip_visual">
          <pose>2 0 0 0 0 0</pose>
          <geometry><sphere><radius>0.15</radius></sphere></geometry>
          <material>
            <ambient>0.9 0.2 0.9 1</ambient>
            <diffuse>0.9 0.2 0.9 1</diffuse>
          </material>
        </visual>
      </link>
      <joint name="spin_joint" type="revolute">
        <parent>base</parent>
        <child>arm</child>
        <axis>
          <xyz>0 0 1</xyz>
          <dynamics>
            <friction>0.0</friction>
          </dynamics>
        </axis>
      </joint>
      <plugin
          filename="gz-sim-joint-controller-system"
          name="gz::sim::systems::JointController">
        <joint_name>spin_joint</joint_name>
        <initial_velocity>2.0</initial_velocity>
      </plugin>
    </model>

    <!-- Camera model with sensor - publishes images on /camera topic -->
    <model name="camera">
      <static>true</static>
      <pose>-4 0 2.0 0 0.3 0</pose>
      <link name="link">
        <visual name="visual">
          <geometry><box><size>0.1 0.1 0.1</size></box></geometry>
          <material>
            <ambient>0.3 0.3 0.3 1</ambient>
            <diffuse>0.3 0.3 0.3 1</diffuse>
          </material>
        </visual>
        <sensor name="camera" type="camera">
          <camera>
            <horizontal_fov>1.047</horizontal_fov>
            <image>
              <width>960</width>
              <height>540</height>
            </image>
            <clip>
              <near>0.1</near>
              <far>1000</far>
            </clip>
          </camera>
          <always_on>1</always_on>
          <update_rate>30</update_rate>
          <visualize>false</visualize>
          <topic>camera</topic>
        </sensor>
      </link>
    </model>

  </world>
</sdf>
